Workbook

Sheet Read me
A1: Task statements: decisions for the second build
A3: Source: exam guide Version 1.0, July 2026, Section 6. The text of each point is exact. An independent reviewer confirmed all 240 points.
A5: How to use this file
A6: 1. Open the sheet of a domain. Each row is one Knowledge (K) or Skills (S) point.
A7: 2. Fill in only the yellow columns: "Your decision", "Where in the pipeline" and "Your notes".
A8: 3. "Your decision" has a list: Use, Do not use, Not sure.
A9: 4. The grey row above each group is the task statement. Its yellow cell is for a note on the full task statement.
A11: The columns that are already filled
A12: "Old build": the result of the audit of 2 October 2026 for this point.
A13: "Fit": strong = a skilled architect would use the practice for this work. weak = small value. none = no use.
A14: "Suggested decision": a first suggestion from the audit. It is not a decision. Rule: "Do not use" for a point that does not fit, "Use" for each other point. Points with a weak fit need your judgment most.
A15: "What it would be in the build": one or two sentences from the audit. Empty where the old build applied the practice with no gap.
... A20: Progress
A21: Domain | B21: Points | C21: Use | D21: Do not use | E21: Not sure | F21: No decision yet
A22: Domain 1 | B22: 48 | C22: =COUNTIF('Domain 1'!$H$5:$H$58,"Use") -> 0 | D22: =COUNTIF('Domain 1'!$H$5:$H$58,"Do not use") -> 0 | E22: =COUNTIF('Domain 1'!$H$5:$H$58,"Not sure") -> 0 | F22: =B22-C22-D22-E22 -> 48
A23: Domain 2 | B23: 43 | C23: =COUNTIF('Domain 2'!$H$5:$H$51,"Use") -> 0 | D23: =COUNTIF('Domain 2'!$H$5:$H$51,"Do not use") -> 0 | E23: =COUNTIF('Domain 2'!$H$5:$H$51,"Not sure") -> 0 | F23: =B23-C23-D23-E23 -> 43
A24: Domain 3 | B24: 49 | C24: =COUNTIF('Domain 3'!$H$5:$H$58,"Use") -> 0 | D24: =COUNTIF('Domain 3'!$H$5:$H$58,"Do not use") -> 0 | E24: =COUNTIF('Domain 3'!$H$5:$H$58,"Not sure") -> 0 | F24: =B24-C24-D24-E24 -> 49
A25: Domain 4 | B25: 47 | C25: =COUNTIF('Domain 4'!$H$5:$H$56,"Use") -> 0 | D25: =COUNTIF('Domain 4'!$H$5:$H$56,"Do not use") -> 0 | E25: =COUNTIF('Domain 4'!$H$5:$H$56,"Not sure") -> 0 | F25: =B25-C25-D25-E25 -> 47
A26: Domain 5 | B26: 53 | C26: =COUNTIF('Domain 5'!$H$5:$H$62,"Use") -> 0 | D26: =COUNTIF('Domain 5'!$H$5:$H$62,"Do not use") -> 0 | E26: =COUNTIF('Domain 5'!$H$5:$H$62,"Not sure") -> 0 | F26: =B26-C26-D26-E26 -> 53
A27: Total | B27: =SUM(B22:B26) -> 240 | C27: =SUM(C22:C26) -> 0 | D27: =SUM(D22:D26) -> 0 | E27: =SUM(E22:E26) -> 0 | F27: =SUM(F22:F26) -> 240

Sheet Domain 1
A1: Domain 1: Agentic Architecture & Orchestration
A3: ID | B3: Kind | C3: Point (exact guide text) | D3: Old build | E3: Fit | F3: Suggested decision | G3: What it would be in the build | H3: Your decision | I3: Where in the pipeline | J3: Your notes
A4: Task statement 1.1: Design and implement agentic loops for autonomous task execution
A5: 1.1-K1 | B5: Knowledge | C5: The agentic loop lifecycle: sending requests to Claude, inspecting stop_reason ("tool_use" vs "end_turn"), executing requested tools, and returning results for the next iteration | D5: Not applied | E5: weak | F5: Use | G5: Own code calls the API for each reviewer. It runs the tools that the model asks for while stop_reason is "tool_use" and it stops on "end_turn". The code then sees each call and each result.
A6: 1.1-K2 | B6: Knowledge | C6: How tool results are appended to conversation history so the model can reason about the next action | D6: Not applied | E6: weak | F6: Use | G6: Own loop code adds each tool result (for example the guide text that a reviewer asked for) to the message list before the next request.
A7: 1.1-K3 | B7: Knowledge | C7: The distinction between model-driven decision-making (Claude reasons about which tool to call next based on context) and pre-configured decision trees or tool sequences | D7: Applied in part | E7: strong | F7: Use | G7: Code runs the fixed chain: generate, check the format, verify, join by ID, gate, bank. The model decides only the open questions, for example which new rule a defect needs.
A8: 1.1-S1 | B8: Skills | C8: Implementing agentic loop control flow that continues when stop_reason is "tool_use" and terminates when stop_reason is "end_turn" | D8: Not applied | E8: weak | F8: Use | G8: A small runner in the repo: send the request, run the tools while stop_reason is "tool_use", stop on "end_turn", write the result and a run record.
A9: 1.1-S2 | B9: Skills | C9: Adding tool results to conversation context between iterations so the model can incorporate new information into its reasoning | D9: Not applied | E9: weak | F9: Use | G9: In an own runner, each tool result goes into the message list before the next request, so that the reviewer can use the guide text that it asked for.
A10: 1.1-S3 | B10: Skills | C10: Avoiding anti-patterns such as parsing natural language signals to determine loop termination, setting arbitrary iteration caps as the primary stopping mechanism, or checking for assistant text content as a completion indicator | D10: Applied in part | E10: strong | F10: Use | G10: A run is complete only when code reads its output and finds the expected count of valid records. A loop ends on counts from the verdict fields, never on an agent's last message or on a file that exists.
A11: Task statement 1.2: Orchestrate multi-agent systems with coordinator-subagent patterns
A12: 1.2-K1 | B12: Knowledge | C12: Hub-and-spoke architecture where a coordinator agent manages all inter-subagent communication, error handling, and information routing | D12: Applied in part | E12: strong | F12: Use | G12: The coordinator's code checks each result file (size, count, format) before it passes anything on. A failed run returns a short failure record. Each agent can read only its own packet.
A13: 1.2-K2 | B13: Knowledge | C13: How subagents operate with isolated context—they do not inherit the coordinator's conversation history automatically | D13: Applied in part | E13: strong | F13: Use | G13: A list for each role of what the agent must receive. Code builds the packet from the list and fails when a part is missing.
A14: 1.2-K3 | B14: Knowledge | C14: The role of the coordinator in task decomposition, delegation, result aggregation, and deciding which subagents to invoke based on query complexity | D14: Applied in part | E14: strong | F14: Use | G14: The coordinator's code joins each result by question ID, counts the verdicts for each slice and stops when a count is wrong.
A15: 1.2-K4 | B15: Knowledge | C15: Risks of overly narrow task decomposition by the coordinator, leading to incomplete coverage of broad research topics | D15: Applied in part | E15: strong | F15: Use | G15: Before a paper is final, code prints a table of task statement by scenario with counts. An empty cell goes back to a generator as a new slice, or the gap is written into the record of the paper.
A16: 1.2-S1 | B16: Skills | C16: Designing coordinator agents that analyze query requirements and dynamically select which subagents to invoke rather than always routing through the full pipeline | D16: Applied in part | E16: strong | F16: Use | G16: For each rejected question the coordinator reads the failed rule. A build fault goes back to one generator with the reason. A duplicate is dropped. A fact fault goes to the gap log.
A17: 1.2-S2 | B17: Skills | C17: Partitioning research scope across subagents to minimize duplication (e.g., assigning distinct subtopics or source types to each agent) | D17: Applied in part | E17: strong | F17: Use | G17: The coordinator keeps a table of the scenes already used for each task statement. Each new slice gets one named point of the guide that is still free, not only a task statement number.
A18: 1.2-S3 | B18: Skills | C18: Implementing iterative refinement loops where the coordinator evaluates synthesis output for gaps, re-delegates to search and analysis subagents with targeted queries, and re-invokes synthesis until coverage is sufficient | D18: Applied in part | E18: strong | F18: Use | G18: After each batch the coordinator compares the accepted questions with the blueprint table. It sends one new slice for each empty cell, until the table is full or the gap is logged.
A19: 1.2-S4 | B19: Skills | C19: Routing all subagent communication through the coordinator for observability, consistent error handling, and controlled information flow | D19: Applied in part | E19: strong | F19: Use | G19: Code writes one run record for each agent call: prompt, input IDs, output IDs, counts, start and end time. The coordinator reads the record, not the agent's last message.
A20: Task statement 1.3: Configure subagent invocation, context passing, and spawning
A21: 1.3-K1 | B21: Knowledge | C21: The Task tool as the mechanism for spawning subagents, and the requirement that allowedTools must include "Task" for a coordinator to invoke subagents | D21: Applied | E21: strong | F21: Use
A22: 1.3-K2 | B22: Knowledge | C22: That subagent context must be explicitly provided in the prompt—subagents do not automatically inherit parent context or share memory between invocations | D22: Applied in part | E22: strong | F22: Use | G22: Each generator prompt holds the digest part for its task statements. Each review packet holds the earlier verifier note for the question.
A23: 1.3-K3 | B23: Knowledge | C23: The AgentDefinition configuration including descriptions, system prompts, and tool restrictions for each subagent type | D23: By instruction only | E23: strong | F23: Use | G23: One saved definition for each role: a description, a system prompt and the allowed tools (none for a generator, read-only for a verifier or reviewer, one result path for an editor). The files stay with the pipeline code.
A24: 1.3-K4 | B24: Knowledge | C24: Fork-based session management for exploring divergent approaches from a shared analysis baseline | D24: Not applied | E24: weak | F24: Use | G24: Freeze one copy of the bank and the rule list. Run two generator prompt variants on the same slices from that copy. Compare the rejections by rule.
A25: 1.3-S1 | B25: Skills | C25: Including complete findings from prior agents directly in the subagent's prompt (e.g., passing web search results and document analysis outputs to the synthesis subagent) | D25: Applied in part | E25: strong | F25: Use | G25: For the duplicate check the verifier gets the full text of the banked questions of the same task statement (5 to 11 questions). The review packet holds the earlier verifier note.
A26: 1.3-S2 | B26: Skills | C26: Using structured data formats to separate content from metadata (source URLs, document names, page numbers) when passing context between agents to preserve attribution | D26: Applied in part | E26: strong | F26: Use | G26: Each question gets an ID when it is generated. Each verdict object must repeat that ID. Code joins by ID and stops on a missing or unknown ID.
A27: 1.3-S3 | B27: Skills | C27: Spawning parallel subagents by emitting multiple Task tool calls in a single coordinator response rather than across separate turns | D27: Applied in part | E27: strong | F27: Use | G27: The five digest agents, and the generators of one batch, start in one coordinator response. The run record keeps the start and end time of each agent.
A28: 1.3-S4 | B28: Skills | C28: Designing coordinator prompts that specify research goals and quality criteria rather than step-by-step procedural instructions, to enable subagent adaptability | D28: Applied in part | E28: strong | F28: Use | G28: Each prompt stays in the repo next to its results, so that a later check can read the goal and the criteria that an agent got.
A29: Task statement 1.4: Implement multi-step workflows with enforcement and handoff patterns
A30: 1.4-K1 | B30: Knowledge | C30: The difference between programmatic enforcement (hooks, prerequisite gates) and prompt-based guidance for workflow ordering | D30: Applied in part | E30: strong | F30: Use | G30: One script runs the steps in order. A step starts only when the step before it wrote a valid output: the count of records, the format, one verdict for each question.
A31: 1.4-K2 | B31: Knowledge | C31: When deterministic compliance is required (e.g., identity verification before financial operations), prompt instructions alone have a non-zero failure rate | D31: Applied in part | E31: strong | F31: Use | G31: Each rule that code can decide is a code check: the allowed values of each field, word counts, banned punctuation, one verdict for each question, the same answer letter as the original.
A32: 1.4-K3 | B32: Knowledge | C32: Structured handoff protocols for mid-process escalation that include customer details, root cause analysis, and recommended actions | D32: Applied in part | E32: strong | F32: Use | G32: Each flagged question in the answer key shows the rule in doubt, the verifier's evidence in one or two sentences, and the proposed fix.
A33: 1.4-S1 | B33: Skills | C33: Implementing programmatic prerequisites that block downstream tool calls until prerequisite steps have completed (e.g., blocking process_refund until get_customer has returned a verified customer ID) | D33: Applied in part | E33: strong | F33: Use | G33: Code refuses to build a paper unless each question has one verdict joined by ID, the verdict is accept or an owner ruling, the answer letter equals the original, and each input file has the expected count of records.
A34: 1.4-S2 | B34: Skills | C34: Decomposing multi-concern customer requests into distinct items, then investigating each in parallel using shared context before synthesizing a unified resolution | D34: Applied in part | E34: strong | F34: Use | G34: One pass for each concern that needs a view of a whole paper: features outside the guide, the count of confidence distractors, repeated scenes. Then one merge step by code that also updates each field.
A35: 1.4-S3 | B35: Skills | C35: Compiling structured handoff summaries (customer ID, root cause, refund amount, recommended action) when escalating to human agents who lack access to the conversation transcript | D35: Applied in part | E35: strong | F35: Use | G35: For each flagged question the handoff gives: paper and number, the rule in doubt, the verifier's evidence, the proposed fix. Code takes each count in a handoff file from the data.
A36: Task statement 1.5: Apply Agent SDK hooks for tool call interception and data normalization
A37: 1.5-K1 | B37: Knowledge | C37: Hook patterns (e.g., PostToolUse) that intercept tool results for transformation before the model processes them | D37: Applied in part | E37: strong | F37: Use | G37: One function runs on each agent output before a later step reads it. It parses the output, maps each field to the allowed form, checks the ID and the count, and stops on a fault.
A38: 1.5-K2 | B38: Knowledge | C38: Hook patterns that intercept outgoing tool calls to enforce compliance rules (e.g., blocking refunds above a threshold) | D38: Applied in part | E38: strong | F38: Use | G38: Code checks each agent output before a later step may use it. A fault (no verdict, unknown ID, a value outside the list, a changed answer letter) stops the question and reports it.
A39: 1.5-K3 | B39: Knowledge | C39: The distinction between using hooks for deterministic guarantees versus relying on prompt instructions for probabilistic compliance | D39: Applied in part | E39: strong | F39: Use | G39: A short list of the rules that must always hold. Each one has a code check and a test. The briefs keep only the rules that need judgement.
A40: 1.5-S1 | B40: Skills | C40: Implementing PostToolUse hooks to normalize heterogeneous data formats (Unix timestamps, ISO 8601, numeric status codes) from different MCP tools before the agent processes them | D40: Applied in part | E40: strong | F40: Use | G40: Code maps each agent output to one record form before the next step: an ID, the task statement as '1.3', the domain as 'D1', the answer as a list, the verdict from a fixed list. A value that does not map stops the batch.
A41: 1.5-S2 | B41: Skills | C41: Implementing tool call interception hooks that block policy-violating actions (e.g., refunds exceeding $500) and redirect to alternative workflows (e.g., human escalation) | D41: Applied in part | E41: strong | F41: Use | G41: A gate before the bank and before each paper build. No verdict, an unknown ID, a value outside the list or a changed answer letter blocks the question and puts it on a list for the owner.
...

Sheet Domain 2
A1: Domain 2: Tool Design & MCP Integration
A3: ID | B3: Kind | C3: Point (exact guide text) | D3: Old build | E3: Fit | F3: Suggested decision | G3: What it would be in the build | H3: Your decision | I3: Where in the pipeline | J3: Your notes
A4: Task statement 2.1: Design effective tool interfaces with clear descriptions and boundaries
A5: 2.1-K1 | B5: Knowledge | C5: Tool descriptions as the primary mechanism LLMs use for tool selection; minimal descriptions lead to unreliable selection among similar tools | D5: By instruction only | E5: weak | F5: Use | G5: Own helper tools (read one guide section, read one banked question, check one question), each with a description of three or four sentences that says what it returns and when to use it.
A6: 2.1-K2 | B6: Knowledge | C6: The importance of including input formats, example queries, edge cases, and boundary explanations in tool descriptions | D6: By instruction only | E6: strong | F6: Use | G6: One tool for each return (`submit_items`, `record_verdict`). Each field has a description with its format, its allowed values, one example and its limit: for example, `trap` is one of seven labels or null.
A7: 2.1-K3 | B7: Knowledge | C7: How ambiguous or overlapping tool descriptions cause misrouting (e.g., analyze_content vs analyze_document with near-identical descriptions) | D7: By instruction only | E7: weak | F7: Use | G7: Each source that an agent can pick has a name and one line that tell it apart from the similar one: "guide, complete, the authority" and "guide, short copy, no task statements".
A8: 2.1-K4 | B8: Knowledge | C8: The impact of system prompt wording on tool selection: keyword-sensitive instructions can create unintended tool associations | D8: Applied in part | E8: strong | F8: Use | G8: Keep the exact wording. After each run, record which tools the agent called and which files it wrote.
A9: 2.1-S1 | B9: Skills | C9: Writing tool descriptions that clearly differentiate each tool's purpose, expected inputs, outputs, and when to use it versus similar alternatives | D9: By instruction only | E9: weak | F9: Use | G9: A short description for each helper of the pipeline: what it is for, the input, the output, and when to use it and not the similar one. The description stays with the helper, so each brief does not repeat it.
A10: 2.1-S2 | B10: Skills | C10: Renaming tools and updating descriptions to eliminate functional overlap (e.g., renaming analyze_content to extract_web_results with a web-specific description) | D10: By instruction only | E10: weak | F10: Use | G10: Rename the short copy so that its name says what it is, or remove it. Give the two `Claude Code in Action.md` files different names.
A11: 2.1-S3 | B11: Skills | C11: Splitting generic tools into purpose-specific tools with defined input/output contracts (e.g., splitting a generic analyze_document into extract_data_points, summarize_content, and verify_claim_against_source) | D11: Not applied | E11: strong | F11: Use | G11: Three small commands with a fixed input and output. `guide_section <task statement>` returns the exact guide text. `banked_item <number>` returns one full question. `check_item <file> <number>` returns word counts, the length ratio and punctuation hits.
A12: 2.1-S4 | B12: Skills | C12: Reviewing system prompts for keyword-sensitive instructions that might override well-written tool descriptions | D12: Not applied | E12: weak | F12: Use | G12: Before a round starts, a second agent reads each brief and lists each sentence that names or implies a tool. The coordinator confirms that each one is intended.
A13: Task statement 2.2: Implement structured error responses for MCP tools
A14: 2.2-K1 | B14: Knowledge | C14: The MCP isError flag pattern for communicating tool failures back to the agent | D14: By instruction only | E14: strong | F14: Use | G14: Each result file starts with a status: ok or failed. Code reads the status and counts the records before it accepts a run.
A15: 2.2-K2 | B15: Knowledge | C15: The distinction between transient errors (timeouts, service unavailability), validation errors (invalid input), business errors (policy violations), and permission errors | D15: By instruction only | E15: strong | F15: Use | G15: A fixed list of failure kinds for a run, each with its next step: not ready yet (wait and read again), bad format (ask again with the error), input missing (send the full input), refused by a rule (do not retry, log the gap).
A16: 2.2-K3 | B16: Knowledge | C16: Why uniform error responses (generic "Operation failed") prevent the agent from making appropriate recovery decisions | D16: Applied in part | E16: strong | F16: Use | G16: Each flag carries a reason code: could not check, second answer possible, weak wrong option, possible repeat. The answer key and the review packet show the code and the note of the verifier.
A17: 2.2-K4 | B17: Knowledge | C17: The difference between retryable and non-retryable errors, and how returning structured metadata prevents wasted retry attempts | D17: By instruction only | E17: strong | F17: Use | G17: Each reject record has a field `retry`: yes for a build fault, no for a repeat or for a fact that is not in the guide. Code sends only the yes records back to a generator, one time.
A18: 2.2-S1 | B18: Skills | C18: Returning structured error metadata including errorCategory (transient/validation/permission), isRetryable boolean, and human-readable descriptions | D18: By instruction only | E18: strong | F18: Use | G18: One failure object in each result format: kind, retry yes or no, a plain description, what the agent tried, what it did finish. The brief shows one example.
A19: 2.2-S2 | B19: Skills | C19: Including retriable: false flags and customer-friendly explanations for business rule violations so the agent can communicate appropriately | D19: By instruction only | E19: weak | F19: Use | G19: A reject for a rule reason carries `retry: no` and one plain sentence for the owner. The gap log and the answer key show that sentence.
A20: 2.2-S3 | B20: Skills | C20: Implementing local error recovery within subagents for transient failures, propagating to the coordinator only errors that cannot be resolved locally along with partial results and what was attempted | D20: Applied in part | E20: strong | F20: Use | G20: One brief line: if a read fails, try one more time. If it fails again, return a failure with what you tried and the questions that you did finish.
A21: 2.2-S4 | B21: Skills | C21: Distinguishing between access failures (needing retry decisions) and valid empty results (representing successful queries with no matches) | D21: Applied in part | E21: strong | F21: Use | G21: Code treats a missing verdict, a missing field and an empty file as a failure, not as a pass. Code builds a paper only when each question has a verdict that is present and joined by its ID.
A22: Task statement 2.3: Distribute tools appropriately across agents and configure tool choice
A23: 2.3-K1 | B23: Knowledge | C23: The principle that giving an agent access to too many tools (e.g., 18 instead of 4-5) degrades tool selection reliability by increasing decision complexity | D23: In the design only | E23: strong | F23: Use | G23: A saved definition for each role with a short tool list: no tools for a generator and a verifier, a read tool and one write path for an editor and a reviewer.
A24: 2.3-K2 | B24: Knowledge | C24: Why agents with tools outside their specialization tend to misuse them (e.g., a synthesis agent attempting web searches) | D24: By instruction only | E24: strong | F24: Use | G24: A reviewer role with read tools only. An editor role that can write one result file. Code refuses a run that changed any other file.
A25: 2.3-K3 | B25: Knowledge | C25: Scoped tool access: giving agents only the tools needed for their role, with limited cross-role tools for specific high-frequency needs | D25: By instruction only | E25: strong | F25: Use | G25: Each role gets the tools of its job only. The verifier also gets one narrow lookup: the full text of one banked question by its number.
A26: 2.3-K4 | B26: Knowledge | C26: tool_choice configuration options: "auto", "any", and forced tool selection ({"type": "tool", "name": "..."}) | D26: By instruction only | E26: strong | F26: Use | G26: A direct API call for each generator with one tool `submit_items` and a forced tool choice. The tool schema holds the 11 fields and the allowed values of `domain`, `trap` and `difficulty`.
A27: 2.3-S1 | B27: Skills | C27: Restricting each subagent's tool set to those relevant to its role, preventing cross-specialization misuse | D27: By instruction only | E27: strong | F27: Use | G27: A saved definition for each role with an allowed tool list: no tools for a generator and a verifier, read-only tools for a reviewer, one write path for an editor.
A28: 2.3-S2 | B28: Skills | C28: Replacing generic tools with constrained alternatives (e.g., replacing fetch_url with load_document that validates document URLs) | D28: By instruction only | E28: strong | F28: Use | G28: Code copies the guide text for the task statements of a slice into the packet, from a guide file with a checked hash. Then the agent needs no read of a guide file. Or one helper command returns guide text from the checked copy only.
A29: 2.3-S3 | B29: Skills | C29: Providing scoped cross-role tools for high-frequency needs (e.g., a verify_fact tool for the synthesis agent) while routing complex cases through the coordinator | D29: Not applied | E29: strong | F29: Use | G29: Verifier: a lookup that returns the full text and the key of one banked question by its number. Editor and reviewer: one shared command that returns word counts, the length ratio and punctuation hits. A case that stays open still goes to the owner.
A30: 2.3-S4 | B30: Skills | C30: Using tool_choice forced selection to ensure a specific tool is called first (e.g., forcing extract_metadata before enrichment tools), then processing subsequent steps in follow-up turns | D30: Not applied | E30: weak | F30: Use | G30: Turn 1 forces a tool `declare_scenes`: the banked scene, the own scene, what differs. Code checks the answers. Turn 2 writes the questions.
A31: 2.3-S5 | B31: Skills | C31: Setting tool_choice: "any" to guarantee the model calls a tool rather than returning conversational text | D31: By instruction only | E31: strong | F31: Use | G31: Each agent call has two tools, `submit_records` and `report_failure`, and the tool choice "any". A run returns records or a failure. It cannot return prose or nothing.
A32: Task statement 2.4: Integrate MCP servers into Claude Code and agent workflows
A33: 2.4-K1 | B33: Knowledge | C33: MCP server scoping: project-level (.mcp.json) for shared team tooling vs user-level (~/.claude.json) for personal/experimental servers | D33: Does not fit | E33: none | F33: Do not use
A34: 2.4-K2 | B34: Knowledge | C34: Environment variable expansion in .mcp.json (e.g., ${GITHUB_TOKEN}) for credential management without committing secrets | D34: Does not fit | E34: none | F34: Do not use
A35: 2.4-K3 | B35: Knowledge | C35: That tools from all configured MCP servers are discovered at connection time and available simultaneously to the agent | D35: In the design only | E35: weak | F35: Use | G35: Before a round, the coordinator lists the servers and tools that a subagent gets, and turns off each one that the role does not need.
A36: 2.4-K4 | B36: Knowledge | C36: MCP resources as a mechanism for exposing content catalogs (e.g., issue summaries, documentation hierarchies, database schemas) to reduce exploratory tool calls | D36: Applied in part | E36: strong | F36: Use | G36: One index made by code before the agents start: each note title with its line range, each task statement with its guide text, each banked question with its number. Each agent gets the index and does not search for it.
A37: 2.4-S1 | B37: Skills | C37: Configuring shared MCP servers in project-scoped .mcp.json with environment variable expansion for authentication tokens | D37: Does not fit | E37: none | F37: Do not use
A38: 2.4-S2 | B38: Skills | C38: Configuring personal/experimental MCP servers in user-scoped ~/.claude.json | D38: Does not fit | E38: none | F38: Do not use
A39: 2.4-S3 | B39: Skills | C39: Enhancing MCP tool descriptions to explain capabilities and outputs in detail, preventing the agent from preferring built-in tools (like Grep) over more capable MCP tools | D39: By instruction only | E39: weak | F39: Use | G39: If the pipeline had its own tool for the guide, its description would say: returns the complete guide text for one task statement; use this tool and not a file read.
A40: 2.4-S4 | B40: Skills | C40: Choosing existing community MCP servers over custom implementations for standard integrations (e.g., Jira), reserving custom servers for team-specific workflows | D40: Applied | E40: weak | F40: Use
A41: 2.4-S5 | B41: Skills | C41: Exposing content catalogs as MCP resources to give agents visibility into available data without requiring exploratory tool calls | D41: Applied in part | E41: strong | F41: Use | G41: A read-only list of the bank: number, task statement, scenario, full stem, key. A second list of the 30 task statements with the exact guide text. A script or a resource returns one entry on request.
...

Sheet Domain 3
A1: Domain 3: Claude Code Configuration & Workflows
A3: ID | B3: Kind | C3: Point (exact guide text) | D3: Old build | E3: Fit | F3: Suggested decision | G3: What it would be in the build | H3: Your decision | I3: Where in the pipeline | J3: Your notes
A4: Task statement 3.1: Configure CLAUDE.md files with appropriate hierarchy, scoping, and modular organization
A5: 3.1-K1 | B5: Knowledge | C5: The CLAUDE.md configuration hierarchy: user-level (~/.claude/CLAUDE.md), project-level (.claude/CLAUDE.md or root CLAUDE.md), and directory-level (subdirectory CLAUDE.md files) | D5: By instruction only | E5: strong | F5: Use | G5: One project rules file that each session and each agent loads without a prompt line: the guide wins, no feature that the guide does not name, the question format, never change an answer letter. Rules for one round go in a file for that folder.
A6: 3.1-K2 | B6: Knowledge | C6: That user-level settings apply only to that user—instructions in ~/.claude/CLAUDE.md are not shared with teammates via version control | D6: Applied in part | E6: weak | F6: Use | G6: Keep each rule, prompt and script in the project folder under version control. Keep nothing that an agent or a later session needs in a place that only one session can read.
A7: 3.1-K3 | B7: Knowledge | C7: The @import syntax for referencing external files to keep CLAUDE.md modular (e.g., importing specific standards files relevant to each package) | D7: By instruction only | E7: strong | F7: Use | G7: One file holds each shared list, for example the features of ruling 1. Each brief refers to it. A new entry goes in one place, and each agent reads the current list.
A8: 3.1-K4 | B8: Knowledge | C8: .claude/rules/ directory for organizing topic-specific rule files as an alternative to a monolithic CLAUDE.md | D8: By instruction only | E8: strong | F8: Use | G8: One focused file for each rule topic: scope and owner rulings, question format, review criteria, output shapes. Each run loads all of them.
A9: 3.1-S1 | B9: Skills | C9: Diagnosing configuration hierarchy issues (e.g., a new team member not receiving instructions because they're in user-level rather than project-level configuration) | D9: Not applied | E9: weak | F9: Use | G9: When an agent does not follow a rule, first check where the rule lives and whether this run loaded it. Do this before you make the rule text stronger.
A10: 3.1-S2 | B10: Skills | C10: Using @import to selectively include relevant standards files in each package's CLAUDE.md based on maintainer domain knowledge | D10: By instruction only | E10: strong | F10: Use | G10: Each role file takes in only the rule files that it needs, by reference: a generator takes scope and format rules, a verifier takes the criteria, an editor takes both.
A11: 3.1-S3 | B11: Skills | C11: Splitting large CLAUDE.md files into focused topic-specific files in .claude/rules/ (e.g., testing.md, api-conventions.md, deployment.md) | D11: Applied in part | E11: strong | F11: Use | G11: Take the rules out of file 06 into focused files: scope, question format, generator rules, checker criteria C1 to C15, output shapes. File 06 stays a design and a log.
A12: 3.1-S4 | B12: Skills | C12: Using the /memory command to verify which memory files are loaded and diagnose inconsistent behavior across sessions | D12: Not applied | E12: strong | F12: Use | G12: Each run writes a record of the rule files, the inputs and the full prompt that it loaded. When two runs behave in different ways, compare the two records.
A13: Task statement 3.2: Create and configure custom slash commands and skills
A14: 3.2-K1 | B14: Knowledge | C14: Project-scoped commands in .claude/commands/ (shared via version control) vs user-scoped commands in ~/.claude/commands/ (personal) | D14: Applied in part | E14: strong | F14: Use | G14: One saved, named prompt file in the project for each repeated step: generate a batch, verify a batch, review a slice, edit a slice, fix a list. The files are under version control.
A15: 3.2-K2 | B15: Knowledge | C15: Skills in .claude/skills/ with SKILL.md files that support frontmatter configuration including context: fork, allowed-tools, and argument-hint | D15: By instruction only | E15: strong | F15: Use | G15: One skill for each repeated step, with its settings in the file: run in a separate context, the tools it may use, and the arguments it needs (mock, scenario, slice).
A16: 3.2-K3 | B16: Knowledge | C16: The context: fork frontmatter option for running skills in an isolated sub-agent context, preventing skill outputs from polluting the main conversation | D16: Applied | E16: strong | F16: Use
A17: 3.2-K4 | B17: Knowledge | C17: Personal skill customization: creating personal variants in ~/.claude/skills/ with different names to avoid affecting teammates | D17: Does not fit | E17: none | F17: Do not use
A18: 3.2-S1 | B18: Skills | C18: Creating project-scoped slash commands in .claude/commands/ for team-wide availability via version control | D18: Applied in part | E18: strong | F18: Use | G18: A command file for each repeated step, with the mock, scenario and slice as arguments. The same file starts run 1 and run 24, and a change to it is a recorded change.
A19: 3.2-S2 | B19: Skills | C19: Using context: fork to isolate skills that produce verbose output (e.g., codebase analysis) or exploratory context (e.g., brainstorming alternatives) from the main session | D19: Applied | E19: strong | F19: Use
A20: 3.2-S3 | B20: Skills | C20: Configuring allowed-tools in skill frontmatter to restrict tool access during skill execution (e.g., limiting to file write operations to prevent destructive actions) | D20: By instruction only | E20: strong | F20: Use | G20: The file of the review step allows read tools and one write path. The file of the generate step allows no tools. The limit is a setting, not a sentence.
A21: 3.2-S4 | B21: Skills | C21: Using argument-hint frontmatter to prompt developers for required parameters when they invoke the skill without arguments | D21: Not applied | E21: weak | F21: Use | G21: Each saved step states its required arguments (mock, scenario, slice file, result path) and stops with a clear message when one is missing.
A22: 3.2-S5 | B22: Skills | C22: Choosing between skills (on-demand invocation for task-specific workflows) and CLAUDE.md (always-loaded universal standards) | D22: By instruction only | E22: strong | F22: Use | G22: Rules that hold for every agent go in one standing file: the guide wins, the owner rulings, never change an answer letter. The steps of one role go in a file that the role calls when it runs.
A23: Task statement 3.3: Apply path-specific rules for conditional convention loading
A24: 3.3-K1 | B24: Knowledge | C24: .claude/rules/ files with YAML frontmatter paths fields containing glob patterns for conditional rule activation | D24: Not applied | E24: weak | F24: Use | G24: A rule file with a path pattern for each kind of file: the bank file (one record on one line, allowed values), the paper files (question format), the Mock 5 slices (rule R12).
A25: 3.3-K2 | B25: Knowledge | C25: How path-scoped rules load only when editing matching files, reducing irrelevant context and token usage | D25: Not applied | E25: weak | F25: Use | G25: A rule for one kind of file loads only when an agent works on that kind. A reviewer of Mock 2 does not load the rule for two-answer questions.
A26: 3.3-K3 | B26: Knowledge | C26: The advantage of glob-pattern rules over directory-level CLAUDE.md files for conventions that span multiple directories (e.g., test files spread throughout a codebase) | D26: Not applied | E26: weak | F26: Use | G26: One rule with a pattern such as `_work/**/*.json` holds the field names of a question record for each work folder. A schema that code checks does the same job better.
A27: 3.3-S1 | B27: Skills | C27: Creating .claude/rules/ files with YAML frontmatter path scoping (e.g., paths: ["terraform/\*\*/\*"]) so rules load only when editing matching files | D27: Not applied | E27: weak | F27: Use | G27: `paths: ["Mocks/item-bank.jsonl"]`: one record on one line, end with a newline, use the allowed values. The rule loads when an agent edits the bank.
A28: 3.3-S2 | B28: Skills | C28: Using glob patterns in path-specific rules to apply conventions to files by type regardless of directory location (e.g., \*\*/\*.test.tsx for all test files) | D28: Not applied | E28: weak | F28: Use | G28: `**/Mock *.md` and `**/*Answer Key.md`: keep the warning line of each flagged question. `**/*.jsonl`: one record on one line.
A29: 3.3-S3 | B29: Skills | C29: Choosing path-specific rules over subdirectory CLAUDE.md files when conventions must apply to files spread across the codebase | D29: Not applied | E29: weak | F29: Use | G29: If the question rules must hold for each copy of a paper in any folder, use one rule with a file pattern and not one rules file in each folder.
A30: Task statement 3.4: Determine when to use plan mode vs direct execution
A31: 3.4-K1 | B31: Knowledge | C31: Plan mode is designed for complex tasks involving large-scale changes, multiple valid approaches, architectural decisions, and multi-file modifications | D31: Applied in part | E31: strong | F31: Use | G31: Before each large phase, a short plan that the owner accepts: scope, rules, order of steps, checks. The status changes from "in design" to "accepted" before the first run.
A32: 3.4-K2 | B32: Knowledge | C32: Direct execution is appropriate for simple, well-scoped changes (e.g., adding a single validation check to one function) | D32: Applied in part | E32: strong | F32: Use | G32: Keep direct work for a fix with one clear target. For a change to many questions, write the rules and the checks first.
A33: 3.4-K3 | B33: Knowledge | C33: Plan mode enables safe codebase exploration and design before committing to changes, preventing costly rework | D33: Applied in part | E33: strong | F33: Use | G33: Measure the guide's 12 samples and run a small pilot before the first full batch, not after Mock 3. In September, review first and write the rubric before any rewrite.
A34: 3.4-K4 | B34: Knowledge | C34: The Explore subagent for isolating verbose discovery output and returning summaries to preserve main conversation context | D34: Applied | E34: strong | F34: Use
A35: 3.4-S1 | B35: Skills | C35: Selecting plan mode for tasks with architectural implications (e.g., microservice restructuring, library migrations affecting 45+ files, choosing between integration approaches with different infrastructure requirements) | D35: Applied in part | E35: strong | F35: Use | G35: Treat the September review as a design task: agree the rounds, the rubric, the rulings and the output format with the owner before the first editor run.
A36: 3.4-S2 | B36: Skills | C36: Selecting direct execution for well-understood changes with clear scope (e.g., a single-file bug fix with a clear stack trace, adding a date validation conditional) | D36: Applied in part | E36: strong | F36: Use | G36: Before a direct fix of a surface pattern, measure the pattern on the guide's samples and on all papers. Before a change to many questions, write the rubric and the checks first.
A37: 3.4-S3 | B37: Skills | C37: Using the Explore subagent for verbose discovery phases to prevent context window exhaustion during multi-phase tasks | D37: Applied | E37: strong | F37: Use
A38: 3.4-S4 | B38: Skills | C38: Combining plan mode for investigation with direct execution for implementation (e.g., planning a library migration, then executing the planned approach) | D38: Applied in part | E38: strong | F38: Use | G38: Close the plan before the first full run: rules, checks, test set. Then run. A new rule after that is a recorded change to the plan.
A39: Task statement 3.5: Apply iterative refinement techniques for progressive improvement
A40: 3.5-K1 | B40: Knowledge | C40: Concrete input/output examples as the most effective way to communicate expected transformations when prose descriptions are interpreted inconsistently | D40: Applied in part | E40: strong | F40: Use | G40: From run 1, each generator prompt has two or three guide samples as the model of form and level. Each editor brief has two or three pairs of a question before and after a correct edit.
A41: 3.5-K2 | B41: Knowledge | C41: Test-driven iteration: writing test suites first, then iterating by sharing test failures to guide progressive improvement | D41: Applied in part | E41: strong | F41: Use | G41: Before the first batch: a fixed set of questions with known verdicts for the verifier, and code that measures each batch against the guide's 12 samples. Each failed test goes back to the generator or to the rule writer.
...

Sheet Domain 4
A1: Domain 4: Prompt Engineering & Structured Output
A3: ID | B3: Kind | C3: Point (exact guide text) | D3: Old build | E3: Fit | F3: Suggested decision | G3: What it would be in the build | H3: Your decision | I3: Where in the pipeline | J3: Your notes
A4: Task statement 4.1: Design prompts with explicit criteria to improve precision and reduce false positives
A5: 4.1-K1 | B5: Knowledge | C5: The importance of explicit criteria over vague instructions (e.g., "flag comments only when claimed behavior contradicts actual code behavior" vs "check that comments are accurate") | D5: Applied in part | E5: strong | F5: Use | G5: Each rule states its test and the evidence it needs, also C5 and R5 (a word-count limit from the start). The rubric is written before the first edit run.
A6: 4.1-K2 | B6: Knowledge | C6: How general instructions like "be conservative" or "only report high-confidence findings" fail to improve precision compared to specific categorical criteria | D6: Applied in part | E6: strong | F6: Use | G6: Replace "look harder" by a named test for flagged questions. A needs-review verdict names the rule that is in doubt and the fact that is missing.
A7: 4.1-K3 | B7: Knowledge | C7: The impact of false positive rates on developer trust: high false positive categories undermine confidence in accurate categories | D7: Applied in part | E7: strong | F7: Use | G7: The owner labels a sample of rejected and flagged questions. Code reports the share of wrong findings for each rule. A warning goes into an answer key only when its rule passes that check.
A8: 4.1-S1 | B8: Skills | C8: Writing specific review criteria that define which issues to report (bugs, security) versus skip (minor style, local patterns) rather than relying on confidence-based filtering | D8: Applied in part | E8: strong | F8: Use | G8: The verifier prompt holds a skip list (for example: the same rule in a new scene, commas in the key). A needs-review verdict must name the rule in doubt.
A9: 4.1-S2 | B9: Skills | C9: Temporarily disabling high false-positive categories to restore developer trust while improving prompts for those categories | D9: Not applied | E9: strong | F9: Use | G9: When C5 gave wrong rejections, set its result to needs-review and keep the questions. Check the new wording of C5 on a sample. Then set it back to reject. Leave the warning line out of the answer keys until a labelled sample shows that the flag predicts a defect.
A10: 4.1-S3 | B10: Skills | C10: Defining explicit severity criteria with concrete code examples for each severity level to achieve consistent classification | D10: Not applied | E10: strong | F10: Use | G10: Three levels in the rubric, each with one example question: blocker (two defensible answers, a fact that is not in the guide), major (a tell, a key that the stem gives away), minor (wording of an explanation). The route depends on the level.
A11: Task statement 4.2: Apply few-shot prompting to improve output consistency and quality
A12: 4.2-K1 | B12: Knowledge | C12: Few-shot examples as the most effective technique for achieving consistently formatted, actionable output when detailed instructions alone produce inconsistent results | D12: Applied in part | E12: strong | F12: Use | G12: Keep each prompt with its examples. Give an example to each role that showed uneven output: a filled question record for the generator, a filled verdict for the verifier.
A13: 4.2-K2 | B13: Knowledge | C13: The role of few-shot examples in demonstrating ambiguous-case handling (e.g., tool selection for ambiguous requests, branch-level test coverage gaps) | D13: In the design only | E13: strong | F13: Use | G13: Two or three borderline pairs in the verifier prompt and in the review brief, each with the verdict and the reason. For example one pair that repeats a scene (reject) and one pair that tests the same rule in a new scene (accept).
A14: 4.2-K3 | B14: Knowledge | C14: How few-shot examples enable the model to generalize judgment to novel patterns rather than matching only pre-specified cases | D14: Applied in part | E14: strong | F14: Use | G14: Code compares each new stem and its options with the 12 guide samples. The verifier gets one more rule: reject a question that reuses the scene or the option set of a sample.
A15: 4.2-K4 | B15: Knowledge | C15: The effectiveness of few-shot examples for reducing hallucination in extraction tasks (e.g., handling informal measurements, varied document structures) | D15: Not applied | E15: strong | F15: Use | G15: Each digest prompt holds two or three example excerpts with their citation: a bulleted list quoted line for line, a long command quoted in full, a cut marked with [...]. The generator prompt shows one `guide_bullet` that is an exact quote.
A16: 4.2-S1 | B16: Skills | C16: Creating 2-4 targeted few-shot examples for ambiguous scenarios that show reasoning for why one action was chosen over plausible alternatives | D16: In the design only | E16: strong | F16: Use | G16: Keep the generator prompt on file with its two or three sample questions and their official explanations. Give the checkers two to four worked borderline cases with the reason for each verdict.
A17: 4.2-S2 | B17: Skills | C17: Including few-shot examples that demonstrate specific desired output format (location, issue, severity, suggested fix) to achieve consistency | D17: Not applied | E17: strong | F17: Use | G17: One filled question record in the generator prompt (domain "D1", task_statement "1.3", trap "recency") and one with trap null. One filled finding record in each review brief.
A18: 4.2-S3 | B18: Skills | C18: Providing few-shot examples distinguishing acceptable code patterns from genuine issues to reduce false positives while enabling generalization | D18: Not applied | E18: strong | F18: Use | G18: Each checker prompt holds two or three pairs: a question that looks like a defect and is acceptable, and one that is a real defect, with the reason. For example a calibrated-confidence key next to a self-reported confidence option.
A19: 4.2-S4 | B19: Skills | C19: Using few-shot examples to demonstrate correct handling of varied document structures (inline citations vs bibliographies, methodology sections vs embedded details) | D19: Not applied | E19: weak | F19: Use | G19: Each digest prompt shows one correct excerpt with its citation for each source form: a note block, a lesson with headings, a doc page.
A20: 4.2-S5 | B20: Skills | C20: Adding few-shot examples showing correct extraction from documents with varied formats to address empty/null extraction of required fields | D20: Not applied | E20: weak | F20: Use | G20: If a digest returned no source for material that a source held in another form, its prompt would get examples of a correct excerpt from each source form.
A21: Task statement 4.3: Enforce structured output using tool use and JSON schemas
A22: 4.3-K1 | B22: Knowledge | C22: Tool use (tool_use) with JSON schemas as the most reliable approach for guaranteed schema-compliant structured output, eliminating JSON syntax errors | D22: By instruction only | E22: strong | F22: Use | G22: Each generator and verifier call goes through the API with one tool. Its input schema is the record, with enums for domain, trap, difficulty and verdict. In the chat session a script could at least check each record against that schema before the record entered the bank.
A23: 4.3-K2 | B23: Knowledge | C23: The distinction between tool_choice: "auto" (model may return text instead of calling a tool), "any" (model must call a tool but can choose which), and forced tool selection (model must call a specific named tool) | D23: Not applied | E23: strong | F23: Use | G23: With tool use, force the one record tool for a generator, so that it cannot answer in prose.
A24: 4.3-K3 | B24: Knowledge | C24: That strict JSON schemas via tool use eliminate syntax errors but do not prevent semantic errors (e.g., line items that don't sum to total, values in wrong fields) | D24: Applied in part | E24: strong | F24: Use | G24: Code checks after the format check: each verdict carries the ID of its question, each `guide_bullet` is found in the guide text, each `eliminating_clause` is found in the stem.
A25: 4.3-K4 | B25: Knowledge | C25: Schema design considerations: required vs optional fields, enum fields with "other" + detail string patterns for extensible categories | D25: Applied in part | E25: strong | F25: Use | G25: The trap field takes one label from the list or "other" plus `trap_detail`, and a separate `trap_note` holds the sentence. The list grows when a new level appears. The verdict record gets a written schema too.
A26: 4.3-S1 | B26: Skills | C26: Defining extraction tools with JSON schemas as input parameters and extracting structured data from the tool_use response | D26: By instruction only | E26: strong | F26: Use | G26: Own code calls the API with a tool `submit_question` whose input schema is the 11-field record, and a tool `submit_verdict` for the verifier. Code reads the tool input as the record.
A27: 4.3-S2 | B27: Skills | C27: Setting tool_choice: "any" to guarantee structured output when multiple extraction schemas exist and the document type is unknown | D27: Not applied | E27: strong | F27: Use | G27: Two tools, `submit_question` and `report_failure`, with tool_choice "any". The generator must return one of the two records and cannot return prose or nothing.
A28: 4.3-S3 | B28: Skills | C28: Forcing a specific tool with tool_choice: {"type": "tool", "name": "extract_metadata"} to ensure a particular extraction runs before enrichment steps | D28: Not applied | E28: weak | F28: Use | G28: First call: a forced tool returns the list of banked scenes for the slice, and code checks it. Second call: write the questions. Forced tool choice needs the API. In the chat session two agent runs in sequence give the same order.
A29: 4.3-S4 | B29: Skills | C29: Designing schema fields as optional (nullable) when source documents may not contain the information, preventing the model from fabricating values to satisfy required fields | D29: Applied in part | E29: strong | F29: Use | G29: `guide_bullet` becomes a list of exact quotes, and code checks each quote against the guide. An empty list with a reason is allowed, so that an answer with no bullet is visible.
A30: 4.3-S5 | B30: Skills | C30: Adding enum values like "unclear" for ambiguous cases and "other" + detail fields for extensible categorization | D30: Applied in part | E30: strong | F30: Use | G30: Each closed list gets "other" plus a detail field. Code counts the "other" values after each batch, and the coordinator adds the frequent ones to the list.
A31: 4.3-S6 | B31: Skills | C31: Including format normalization rules in prompts alongside strict output schemas to handle inconsistent source formatting | D31: Applied in part | E31: strong | F31: Use | G31: The generator prompt states each form ("D1", "1.3", one trap label). Code maps or rejects a record with another form and logs the change.
A32: Task statement 4.4: Implement validation, retry, and feedback loops for extraction quality
A33: 4.4-K1 | B33: Knowledge | C33: Retry-with-error-feedback: appending specific validation errors to the prompt on retry to guide the model toward correction | D33: Applied in part | E33: strong | F33: Use | G33: Each rejected question goes back to a generator one time, with the question, the rule that failed and the verifier's evidence. A new verifier checks the new version.
A34: 4.4-K2 | B34: Knowledge | C34: The limits of retry: retries are ineffective when the required information is simply absent from the source document (vs format or structural errors) | D34: Applied in part | E34: strong | F34: Use | G34: When a verifier note says that information is missing, the coordinator supplies the full banked stems for that task statement and runs the check again. It does not print a warning.
A35: 4.4-K3 | B35: Knowledge | C35: Feedback loop design: tracking which code constructs trigger findings (detected_pattern field) to enable systematic analysis of dismissal patterns | D35: Applied in part | E35: strong | F35: Use | G35: Each verdict has the fields `failed_rule` and `detected_pattern` (for example "self-reported confidence option", "feature not in the guide"). After each batch, code counts findings and overturned findings for each pattern.
A36: 4.4-K4 | B36: Knowledge | C36: The difference between semantic validation errors (values don't sum, wrong field placement) and schema syntax errors (eliminated by tool use) | D36: Applied in part | E36: strong | F36: Use | G36: Two code gates on each record. Format gate: the line parses, the fields exist, the values are in the lists. Meaning gate: counts agree, quotes are found in their source, the verdict joins by ID.
A37: 4.4-S1 | B37: Skills | C37: Implementing follow-up requests that include the original document, the failed extraction, and specific validation errors for model self-correction | D37: Applied in part | E37: strong | F37: Use | G37: In August: a follow-up prompt to a generator with the guide bullets of the slice, the rejected question and the verifier note. One time for each question.
A38: 4.4-S2 | B38: Skills | C38: Identifying when retries will be ineffective (e.g., information exists only in an external document not provided) versus when they will succeed (format mismatches, structural output errors) | D38: Applied in part | E38: strong | F38: Use | G38: Code sorts each failed or unsettled check by cause. Missing input: supply it and check again. Bad form or structure: send back with the findings. No source in the guide: drop and log the gap.
A39: 4.4-S3 | B39: Skills | C39: Adding detected_pattern fields to structured findings to enable analysis of false positive patterns when developers dismiss findings | D39: Applied in part | E39: strong | F39: Use | G39: A `detected_pattern` field in each verifier and reviewer finding. A field `overturned_by` when the owner or a later reviewer rejects the finding. Code reports the patterns with the most overturned findings.
A40: 4.4-S4 | B40: Skills | C40: Designing self-correction validation flows: extracting "calculated_total" alongside "stated_total" to flag discrepancies, adding "conflict_detected" booleans for inconsistent source data | D40: Applied in part | E40: strong | F40: Use | G40: Code gates after each run: records written equal records planned, verdicts equal questions and join by ID, each quoted clause is found in its stem, each `guide_bullet` is found in the guide. A mismatch sets a flag on the record.
A41: Task statement 4.5: Design efficient batch processing strategies
...

Sheet Domain 5
A1: Domain 5: Context Management & Reliability
A3: ID | B3: Kind | C3: Point (exact guide text) | D3: Old build | E3: Fit | F3: Suggested decision | G3: What it would be in the build | H3: Your decision | I3: Where in the pipeline | J3: Your notes
A4: Task statement 5.1: Manage conversation context to preserve critical information across long interactions
A5: 5.1-K1 | B5: Knowledge | C5: Progressive summarization risks: condensing numerical values, percentages, dates, and customer-stated expectations into vague summaries | D5: Applied in part | E5: strong | F5: Use | G5: Keep each count and each rule in one data file. Code writes the summaries and the handoff from that file, so a summary cannot differ from its rows. Code checks that each `guide_bullet` is an exact string of the guide.
A6: 5.1-K2 | B6: Knowledge | C6: The "lost in the middle" effect: models reliably process information at the beginning and end of long inputs but may omit findings from middle sections | D6: Applied in part | E6: strong | F6: Use | G6: Save each generator prompt. Code builds it in the fixed order and puts the stems of the same task statement at the top of the banked list.
A7: 5.1-K3 | B7: Knowledge | C7: How tool results accumulate in context and consume tokens disproportionately to their relevance (e.g., 40+ fields per order lookup when only 5 are relevant) | D7: Applied in part | E7: strong | F7: Use | G7: Budget by relevance, not by length: send the full stem and the key idea of each banked question of the same task statement, and no other stems.
A8: 5.1-K4 | B8: Knowledge | C8: The importance of passing complete conversation history in subsequent API requests to maintain conversational coherence | D8: Applied in part | E8: weak | F8: Use | G8: In a build on the API, a retry sends the first request, the rejected question and the reason of the verifier again in one message list.
A9: 5.1-S1 | B9: Skills | C9: Extracting transactional facts (amounts, dates, order numbers, statuses) into a persistent "case facts" block included in each prompt, outside summarized history | D9: Applied in part | E9: strong | F9: Use | G9: One fixed record for each question: ID, answer letter, task statement, exact guide bullet, verifier flag and reason. Code puts this record into each packet and refuses a packet without it.
